[META]
version=2.0
spawnOnBlockType=2
spawnSunlight=True
spawnDarkness=False
spawnWater=False
spawnLava=False
underFill=True
randomRotation=True
dig=True
tree=False
branch=False
needsFoundation=True
rarity=1
collisionPercentage=2
spawnElevationMin=0
spawnElevationMax=256
spawnInBiome=All
[DATA]
-5,0,0:3
-4,1,0:3
-3,2,0:3
-2,3,0:3
-1,4,0:3
0,5,0:3
1,4,0:3
2,3,0:3
3,2,0:3
4,1,0:3
5,0,0:3
4,-1,0:3
3,-2,0:3
2,-3,0:3
1,-4,0:3
0,-5,0:3
-1,-4,0:3
-2,-3,0:3
-3,-2,0:3
-4,-1,0:3
-4,0,0:112
-3,1,0:112
-3,0,0:112
-2,0,0:112
-1,0,0:112
-1,1,0:112
-2,1,0:112
-2,2,0:112
-1,2,0:112
-1,3,0:112
0,3,0:112
0,4,0:112
1,3,0:112
1,2,0:112
0,2,0:112
1,1,0:112
2,1,0:112
2,2,0:112
0,1,0:112
3,0,0:112
4,0,0:112
3,1,0:112
3,-1,0:112
2,-1,0:112
2,0,0:112
2,-2,0:112
1,-1,0:112
1,0,0:112
1,-2,0:112
1,-3,0:112
0,-4,0:112
0,-3,0:112
0,-2,0:112
-1,-2,0:112
0,-1,0:112
-1,-1,0:112
-2,-1,0:112
-3,-1,0:112
-2,-2,0:112
-1,-3,0:112
0,0,0:56
0,0,1:56
-5,0,1:112
-4,0,1:112
-3,0,1:89
-2,0,1:112
-1,0,1:112
-1,1,1:112
-2,1,1:112
-3,1,1:112
-4,1,1:112
-3,2,1:112
-2,2,1:112
-1,2,1:112
0,2,1:112
1,2,1:112
2,2,1:112
3,2,1:112
0,5,1:112
-1,4,1:112
0,4,1:112
1,4,1:112
-2,3,1:112
-1,3,1:112
0,3,1:89
1,3,1:112
2,3,1:112
0,1,1:112
1,1,1:112
2,1,1:112
3,1,1:112
4,1,1:112
1,0,1:112
2,0,1:112
3,0,1:89
4,0,1:112
5,0,1:112
4,-1,1:112
3,-1,1:112
2,-1,1:112
1,-1,1:112
0,-1,1:112
-1,-1,1:112
-2,-1,1:112
-3,-1,1:112
-4,-1,1:112
-3,-2,1:112
-2,-2,1:112
-1,-2,1:112
0,-2,1:112
1,-2,1:112
2,-2,1:112
3,-2,1:112
-2,-3,1:112
-1,-3,1:112
0,-3,1:89
1,-3,1:112
2,-3,1:112
-1,-4,1:112
0,-4,1:112
1,-4,1:112
0,-5,1:112
-8,0,1:2
-7,0,1:89
-6,0,1:2
-7,1,1:2
-6,1,1:2
-5,1,1:2
-6,2,1:2
-5,2,1:2
-4,2,1:2
-5,3,1:2
-4,3,1:2
-4,4,1:2
-3,4,1:2
-3,3,1:2
-2,4,1:2
-3,5,1:2
-2,5,1:2
-1,5,1:2
-2,6,1:2
-1,6,1:2
0,6,1:2
-1,7,1:2
0,7,1:89
0,8,1:2
1,7,1:2
1,6,1:2
1,5,1:2
2,6,1:2
2,5,1:2
2,4,1:2
3,5,1:2
3,4,1:2
3,3,1:2
4,4,1:2
4,3,1:2
4,2,1:2
5,3,1:2
5,2,1:2
5,1,1:2
6,2,1:2
6,1,1:2
7,1,1:2
6,0,1:2
7,0,1:89
8,0,1:2
7,-1,1:2
6,-1,1:2
5,-1,1:2
6,-2,1:2
5,-2,1:2
4,-2,1:2
5,-3,1:2
4,-3,1:2
3,-3,1:2
4,-4,1:2
3,-4,1:2
2,-4,1:2
3,-5,1:2
2,-5,1:2
1,-5,1:2
2,-6,1:2
1,-6,1:2
0,-6,1:2
-1,-6,1:2
-2,-6,1:2
-1,-5,1:2
-2,-5,1:2
-3,-5,1:2
1,-7,1:2
0,-7,1:89
0,-8,1:2
-1,-7,1:2
-2,-4,1:2
-3,-4,1:2
-4,-4,1:2
-3,-3,1:2
-4,-3,1:2
-5,-3,1:2
-4,-2,1:2
-5,-2,1:2
-6,-2,1:2
-5,-1,1:2
-6,-1,1:2
-7,-1,1:2
-4,0,-1:3
-3,1,-1:3
-2,2,-1:3
-1,3,-1:3
0,4,-1:3
1,3,-1:3
2,2,-1:3
3,1,-1:3
4,0,-1:3
3,-1,-1:3
2,-2,-1:3
1,-3,-1:3
0,-4,-1:3
-1,-3,-1:3
-2,-2,-1:3
-3,-1,-1:3
-3,0,-1:112
-2,0,-1:112
-2,1,-1:112
-1,-1,-1:112
-2,-1,-1:112
-1,-2,-1:112
0,-3,-1:112
0,-2,-1:112
1,-2,-1:112
0,-1,-1:112
1,-1,-1:112
2,-1,-1:112
2,0,-1:112
3,0,-1:112
2,1,-1:112
1,1,-1:112
1,0,-1:112
1,2,-1:112
0,3,-1:112
0,2,-1:112
-1,2,-1:112
-1,1,-1:112
0,1,-1:112
-1,0,-1:112
0,0,-1:112
-3,0,-2:3
-2,1,-2:3
-1,2,-2:3
0,3,-2:3
1,2,-2:3
2,1,-2:3
3,0,-2:3
2,-1,-2:3
1,-2,-2:3
0,-3,-2:3
-1,-2,-2:3
-2,-1,-2:3
-2,0,-2:112
-1,0,-2:112
-1,-1,-2:112
0,-1,-2:112
0,-2,-2:112
0,0,-2:112
0,1,-2:112
-1,1,-2:112
0,2,-2:112
1,1,-2:112
1,0,-2:112
2,0,-2:112
1,-1,-2:112
-2,0,-3:3
-1,1,-3:3
0,2,-3:3
1,1,-3:3
2,0,-3:3
1,-1,-3:3
0,-2,-3:3
-1,-1,-3:3
0,-1,-3:112
-1,0,-3:112
0,1,-3:112
0,0,-3:112
1,0,-3:112
-1,0,-4:3
0,1,-4:3
1,0,-4:3
0,-1,-4:3
0,0,-4:112
0,0,-5:3
0,0,2:56
-1,0,2:14
0,1,2:14
0,-1,2:14
1,0,2:14
0,0,3:56
0,0,4:56
0,0,5:56
0,0,6:56
-1,0,6:18.3
-2,0,6:18.3
-1,1,6:18.3
0,2,6:18.3
0,1,6:18.3
1,1,6:18.3
1,0,6:18.3
2,0,6:18.3
1,-1,6:18.3
0,-2,6:18.3
0,-1,6:18.3
-1,-1,6:18.3
0,0,7:57
-1,0,7:17.3
0,1,7:17.3
1,0,7:17.3
0,-1,7:17.3
-1,-1,7:17.3
0,-2,7:17.3
-2,0,7:17.3
-1,1,7:17.3
0,2,7:17.3
1,1,7:17.3
2,0,7:17.3
1,-1,7:17.3
-3,0,7:18.3
-2,1,7:18.3
-1,2,7:18.3
0,3,7:18.3
1,2,7:18.3
2,1,7:18.3
3,0,7:18.3
2,-1,7:18.3
1,-2,7:18.3
0,-3,7:18.3
-1,-2,7:18.3
-2,-1,7:18.3
2,0,8:18.3
1,-1,8:18.3
0,-2,8:18.3
-1,-1,8:18.3
-2,0,8:18.3
-1,1,8:18.3
0,2,8:18.3
1,1,8:18.3
1,0,8:17.3
0,-1,8:17.3
0,0,8:17.3
-1,0,8:17.3
0,1,8:17.3
0,0,9:17.3
1,0,9:18.3
0,1,9:18.3
0,-1,9:18.3
-1,0,9:18.3
0,0,10:18.3
