[META]
version=2.0
spawnOnBlockType=2
spawnSunlight=True
spawnDarkness=False
spawnWater=False
spawnLava=False
underFill=True
randomRotation=True
dig=True
tree=true
branch=False
needsFoundation=True
rarity=20
collisionPercentage=2
spawnElevationMin=0
spawnElevationMax=2247
spawnInBiome=All
[DATA]
-2,-1,1:106.11
-1,2,1:106.7
1,2,1:106.7
2,1,1:106.14
2,-1,1:106.14
1,-2,1:106.13
-1,-2,1:106.13
-2,1,1:106.11
-3,2,1:106.11
-3,0,1:106.11
-3,-2,1:106.11
-2,3,1:106.7
0,3,1:106.7
2,3,1:106.7
3,2,1:106.14
3,0,1:106.14
3,-2,1:106.14
2,-3,1:106.13
0,-3,1:106.13
-2,-3,1:106.13
-4,-3,1:106.1
-4,-1,1:106.1
-4,1,1:106.1
-4,3,1:106.1
-3,4,1:106.2
-1,4,1:106.2
1,4,1:106.2
3,4,1:106.2
4,3,1:106.4
4,1,1:106.4
4,-1,1:106.4
4,-3,1:106.4
3,-4,1:106.8
1,-4,1:106.8
-1,-4,1:106.8
-3,-4,1:106.8
0,1,1:106.7
0,-1,1:106.13
1,0,1:106.14
-1,0,1:106.11
0,0,1:17.3
-2,-1,2:106.11
-1,2,2:106.7
1,2,2:106.7
2,1,2:106.14
2,-1,2:106.14
1,-2,2:106.13
-1,-2,2:106.13
-2,1,2:106.11
-3,2,2:106.11
-3,0,2:106.11
-3,-2,2:106.11
-2,3,2:106.7
0,3,2:106.7
2,3,2:106.7
3,2,2:106.14
3,0,2:106.14
3,-2,2:106.14
2,-3,2:106.13
0,-3,2:106.13
-2,-3,2:106.13
-4,-3,2:106.1
-4,-1,2:106.1
-4,1,2:106.1
-4,3,2:106.1
-3,4,2:106.2
-1,4,2:106.2
1,4,2:106.2
3,4,2:106.2
4,3,2:106.4
4,1,2:106.4
4,-1,2:106.4
4,-3,2:106.4
3,-4,2:106.8
1,-4,2:106.8
-1,-4,2:106.8
-3,-4,2:106.8
0,1,2:106.7
0,-1,2:106.13
1,0,2:106.14
-1,0,2:106.11
0,0,2:17.3
-2,-1,3:106.11
-1,2,3:106.7
1,2,3:106.7
2,1,3:106.14
2,-1,3:106.14
1,-2,3:106.13
-1,-2,3:106.13
-2,1,3:106.11
-3,2,3:106.11
-3,0,3:106.11
-3,-2,3:106.11
-2,3,3:106.7
0,3,3:106.7
2,3,3:106.7
3,2,3:106.14
3,0,3:106.14
3,-2,3:106.14
2,-3,3:106.13
0,-3,3:106.13
-2,-3,3:106.13
-4,-3,3:106.1
-4,-1,3:106.1
-4,1,3:106.1
-4,3,3:106.1
-3,4,3:106.2
-1,4,3:106.2
1,4,3:106.2
3,4,3:106.2
4,3,3:106.4
4,1,3:106.4
4,-1,3:106.4
4,-3,3:106.4
3,-4,3:106.8
1,-4,3:106.8
-1,-4,3:106.8
-3,-4,3:106.8
0,1,3:106.7
0,-1,3:106.13
1,0,3:106.14
-1,0,3:106.11
0,0,3:17.3
-2,-1,4:106.11
-1,2,4:106.7
1,2,4:106.7
2,1,4:106.14
2,-1,4:106.14
1,-2,4:106.13
-1,-2,4:106.13
-2,1,4:106.11
-3,2,4:106.11
-3,0,4:106.11
-3,-2,4:106.11
-2,3,4:106.7
0,3,4:106.7
2,3,4:106.7
3,2,4:106.14
3,0,4:106.14
3,-2,4:106.14
2,-3,4:106.13
0,-3,4:106.13
-2,-3,4:106.13
-4,-3,4:106.1
-4,-1,4:106.1
-4,1,4:106.1
-4,3,4:106.1
-3,4,4:106.2
-1,4,4:106.2
1,4,4:106.2
3,4,4:106.2
4,3,4:106.4
4,1,4:106.4
4,-1,4:106.4
4,-3,4:106.4
3,-4,4:106.8
1,-4,4:106.8
-1,-4,4:106.8
-3,-4,4:106.8
0,1,4:106.7
0,-1,4:106.13
1,0,4:106.14
-1,0,4:106.11
0,0,4:17.3
-2,-1,5:106.11
-1,2,5:106.7
1,2,5:106.7
2,1,5:106.14
2,-1,5:106.14
1,-2,5:106.13
-1,-2,5:106.13
-2,1,5:106.11
-3,2,5:106.11
-3,0,5:106.11
-3,-2,5:106.11
-2,3,5:106.7
0,3,5:106.7
2,3,5:106.7
3,2,5:106.14
3,0,5:106.14
3,-2,5:106.14
2,-3,5:106.13
0,-3,5:106.13
-2,-3,5:106.13
-4,-3,5:106.1
-4,-1,5:106.1
-4,1,5:106.1
-4,3,5:106.1
-3,4,5:106.2
-1,4,5:106.2
1,4,5:106.2
3,4,5:106.2
4,3,5:106.4
4,1,5:106.4
4,-1,5:106.4
4,-3,5:106.4
3,-4,5:106.8
1,-4,5:106.8
-1,-4,5:106.8
-3,-4,5:106.8
0,1,5:106.7
0,-1,5:106.13
1,0,5:106.14
-1,0,5:106.11
0,0,5:17.3
1,1,6:17.3
1,-1,6:17.3
-1,-1,6:17.3
-1,1,6:17.3
-2,-1,6:106.11
-1,2,6:106.7
1,2,6:106.7
2,1,6:106.14
2,-1,6:106.14
1,-2,6:106.13
-1,-2,6:106.13
0,0,6:18.3
-2,1,6:106.11
-3,2,6:106.11
-3,0,6:106.11
-3,-2,6:106.11
-2,3,6:106.7
0,3,6:106.7
2,3,6:106.7
3,2,6:106.14
3,0,6:106.14
3,-2,6:106.14
2,-3,6:106.13
0,-3,6:106.13
-2,-3,6:106.13
-4,-3,6:106.1
-4,-1,6:106.1
-4,1,6:106.1
-4,3,6:106.1
-3,4,6:106.2
-1,4,6:106.2
1,4,6:106.2
3,4,6:106.2
4,3,6:106.4
4,1,6:106.4
4,-1,6:106.4
4,-3,6:106.4
3,-4,6:106.8
1,-4,6:106.8
-1,-4,6:106.8
-3,-4,6:106.8
0,1,6:106.7
0,-1,6:106.13
1,0,6:106.14
-1,0,6:106.11
-2,2,7:17.3
2,2,7:17.3
2,-2,7:17.3
-2,-2,7:17.3
-3,2,7:106.11
3,-4,7:106.8
-3,-4,7:106.8
-4,3,7:106.1
-4,-3,7:106.1
2,3,7:106.7
2,-3,7:106.13
-3,-2,7:106.11
-3,4,7:106.2
3,4,7:106.2
3,-2,7:106.14
4,3,7:106.4
-2,3,7:106.7
-2,-3,7:106.13
4,-3,7:106.4
-2,1,7:106.11
-2,-1,7:106.11
2,-1,7:106.14
2,1,7:106.14
1,-2,7:106.13
1,2,7:106.7
-1,2,7:106.7
0,2,7:17.3
-2,0,7:17.3
0,-2,7:17.3
2,0,7:17.3
1,-1,7:18.3
1,1,7:18.3
1,0,7:18.3
0,-1,7:18.3
-1,-1,7:18.3
-1,0,7:18.3
-1,1,7:18.3
0,1,7:18.3
0,0,7:18.3
0,3,7:106.7
0,-3,7:106.13
3,2,7:106.14
3,0,7:106.14
-3,0,7:106.11
-1,-2,7:106.13
-4,-1,7:106.1
-4,1,7:106.1
-1,4,7:106.2
1,4,7:106.2
4,-1,7:106.4
4,1,7:106.4
1,-4,7:106.8
-1,-4,7:106.8
3,-3,8:17.3
3,3,8:17.3
-3,3,8:17.3
-3,-3,8:17.3
4,3,8:106.4
4,-3,8:106.4
-2,-3,8:106.13
-2,3,8:106.7
-4,3,8:106.1
-4,-3,8:106.1
2,-3,8:106.13
2,3,8:106.7
-3,4,8:106.2
3,4,8:106.2
3,-2,8:106.14
-3,-2,8:106.11
-3,-4,8:106.8
3,-4,8:106.8
3,2,8:106.14
-3,2,8:106.11
-1,3,8:17.3
1,3,8:17.3
1,-3,8:17.3
-1,-3,8:17.3
-3,-1,8:17.3
-3,1,8:17.3
3,-1,8:17.3
3,1,8:17.3
-2,-2,8:18.3
-2,-1,8:18.3
-2,0,8:18.3
-2,1,8:18.3
-2,2,8:18.3
-1,2,8:18.3
0,2,8:18.3
1,2,8:18.3
2,2,8:18.3
2,1,8:18.3
2,0,8:18.3
2,-1,8:18.3
2,-2,8:18.3
1,-2,8:18.3
0,-2,8:18.3
-1,-2,8:18.3
-1,-1,8:18.3
-1,0,8:18.3
-1,1,8:18.3
0,1,8:18.3
1,1,8:18.3
1,0,8:18.3
1,-1,8:18.3
0,-1,8:18.3
0,0,8:18.3
-3,0,8:106.11
0,3,8:106.7
0,-3,8:106.13
3,0,8:106.14
4,-1,8:106.4
-4,-1,8:106.1
-4,1,8:106.1
-1,4,8:106.2
1,4,8:106.2
4,1,8:106.4
1,-4,8:106.8
-1,-4,8:106.8
-3,-3,9:18.3
-3,-2,9:18.3
-3,-1,9:18.3
-3,0,9:18.3
-3,1,9:18.3
-3,2,9:18.3
-2,2,9:18.3
-2,3,9:18.3
-3,3,9:18.3
-1,3,9:18.3
0,3,9:18.3
1,3,9:18.3
2,3,9:18.3
3,3,9:18.3
3,2,9:18.3
3,1,9:18.3
3,0,9:18.3
3,-1,9:18.3
3,-2,9:18.3
3,-3,9:18.3
2,-3,9:18.3
1,-3,9:18.3
0,-3,9:18.3
-1,-3,9:18.3
-1,-2,9:18.3
-2,-2,9:18.3
-2,-1,9:18.3
-1,-1,9:18.3
-1,0,9:18.3
-2,0,9:18.3
-2,-3,9:18.3
-2,1,9:18.3
-1,2,9:18.3
-1,1,9:18.3
0,0,9:18.3
0,-1,9:18.3
0,-2,9:18.3
0,1,9:18.3
0,2,9:18.3
1,2,9:18.3
2,2,9:18.3
2,1,9:18.3
2,0,9:18.3
2,-1,9:18.3
2,-2,9:18.3
1,-2,9:18.3
1,-1,9:18.3
1,0,9:18.3
1,1,9:18.3
-2,-2,10:18.3
-2,-1,10:18.3
-2,0,10:18.3
-2,1,10:18.3
-2,2,10:18.3
-1,2,10:18.3
0,2,10:18.3
1,2,10:18.3
2,2,10:18.3
2,1,10:18.3
2,0,10:18.3
2,-1,10:18.3
2,-2,10:18.3
1,-2,10:18.3
0,-2,10:18.3
-1,-2,10:18.3
-1,-1,10:18.3
-1,0,10:18.3
-1,1,10:18.3
0,1,10:18.3
1,1,10:18.3
1,0,10:18.3
1,-1,10:18.3
0,-1,10:18.3
0,0,10:17.3
-1,-1,11:18.3
-1,0,11:18.3
-1,1,11:18.3
0,1,11:18.3
1,1,11:18.3
1,0,11:18.3
1,-1,11:18.3
0,-1,11:18.3
0,0,11:18.3
0,0,12:18.3
